<robot name="simple_box">
  <link name="my_box">
    <inertial>
      <origin xyz="0 0 0" rpy="0 0 0" />
      <mass value="1.0" />
      <inertia  ixx="1.0" ixy="0.0"  ixz="0.0"  iyy="100.0"  iyz="0.0"  izz="1.0" />
    </inertial>
    <visual>
      <origin xyz="0 0 0"/>
      <geometry>
        <box size="0.2 0.2 0.2" />
      </geometry>
    </visual>
    <collision>
      <origin xyz="0 0 0"/>
      <geometry>
        <box size="0.2 0.2 0.2" />
      </geometry>
    </collision>
  </link>
  <gazebo reference="my_box">
        <kp>1000000.0</kp>
        <kd>1000000.0</kd>
        <mu1>1000000.0</mu1>
        <mu2>1000000.0</mu2>
    <material>Gazebo/Blue</material>
  </gazebo>
<!-- add the wheels-->
 <link name="inertia_wheel_roll">
        <inertial>
            <origin xyz="0 0 0" rpy="0 0 0"/>
            <mass value="0.5" />
            <inertia ixx="0.000804166666667" ixy="0.0" ixz="0.0" iyy="0.000804166666667" iyz="0.0" izz="0.0016"/>
        </inertial>
        <collision>
            <origin xyz="0 0 0" rpy="0 0 0"/>
            <geometry>
                <cylinder radius="0.08" length="0.01"/>
            </geometry>
        </collision>
	    <visual>
	      <geometry>
	        <cylinder radius="0.08" length="0.01"/>
	      </geometry>
	    </visual>
    </link>
    
    <gazebo reference="inertia_wheel_roll">
        <kp>1000.0</kp>
        <kd>1000.0</kd>
        <mu1>0.5</mu1>
        <mu2>0.5</mu2>
        <material>Gazebo/Red</material>
    </gazebo>

<!-- add a joint to attach wheels and cube-->

 <joint name="inertia_wheel_roll_joint" type="continuous">
        <origin xyz="0.1 0.0 0.0" rpy="0 1.57 0"/>
        <parent link="my_box"/>
        <child  link="inertia_wheel_roll"/>
        <limit effort="200" velocity="1000.0"/>
        <axis xyz="0 0 1"/>
    </joint>

  <!-- Gazebo plugin for ROS Control -->
  <gazebo>
    <plugin name="gazebo_ros_control" filename="libgazebo_ros_control.so">
      <robotNamespace>/simple_box</robotNamespace>
    </plugin>
  </gazebo>
</robot>
